Workbook
Name A_impresión_IM: #REF!
Name A_impresión_IM: #REF!
Name A_impresión_IM: #REF!
Name A_impresión_IM: #REF!
Name A_impresión_IM: #REF!
Name A_impresión_IM: #REF!
Name A_impresión_IM: #REF!
Name A_impresión_IM: #REF!
Name A_impresión_IM: #REF!
Name A_impresión_IM: #REF!
Name A_impresión_IM: #REF!
Name A_impresión_IM: #REF!
Name A_impresión_IM: #REF!
Name A_impresión_IM: #REF!
Name A_impresión_IM: #REF!
Name A_impresión_IM: #REF!
Name A_impresión_IM: #REF!
Name A_impresión_IM: #REF!
Name A_impresión_IM: #REF!
Name A_impresión_IM: #REF!
Name A_impresión_IM: #REF!
Name A_impresión_IM: #REF!
Name A_impresión_IM: #REF!
Name A_impresión_IM: #REF!
Name A_impresión_IM: #REF!
Name A_impresión_IM: #REF!
Name A_impresión_IM: #REF!
Name A_impresión_IM: #REF!
Name A_impresión_IM: #REF!
Name A_impresión_IM: #REF!
Name A_impresión_IM: #REF!
Name A_impresión_IM: #REF!
Name A_impresión_IM: #REF!
Name A_impresión_IM: #REF!
Name A_impresión_IM: #REF!
Name A_impresión_IM: #REF!
Name A_impresión_IM: #REF!
Name ANTONE1: #REF!
Name ANTONE1: #REF!
Name ANTONE1: #REF!
Name ANTONE1: #REF!
Name ANTONE1: #REF!
Name ANTONE1: #REF!
Name ANTONE1: #REF!
Name ANTONE1: #REF!
Name ANTONE1: #REF!
Name ANTONE1: #REF!
Name ANTONE1: #REF!
Name ANTONE1: #REF!
Name ANTONE1: #REF!
Name ANTONE1: #REF!
Name ANTONE1: #REF!
Name ANTONE1: #REF!
Name ANTONE1: #REF!
Name ANTONE1: #REF!
Name ANTONE1: #REF!
Name ANTONE1: #REF!
Name ANTONE1: #REF!
Name ANTONE1: #REF!
Name ANTONE1: #REF!

Sheet REPORTE MES 1 (2)
D2: VENTAS ESPERADAS | E2: V. ACUMULADAS | F2: VENTAS REALES | G2: VENTAS ACUMULADAS
B3: VENTAS | C3: 44927 | D3: 5 | E3: =D3 -> 5 | F3: 4 | G3: =F3 -> 4 | P3: VENTAS DEL PERIODO
C4: 44958 | D4: 5 | E4: =E3+D4 -> 10 | F4: 5 | G4: =G3+F4 -> 9 | P4: =F9 -> 3
C5: 44986 | D5: 6 | E5: =E4+D5 -> 16 | F5: 5 | G5: =G4+F5 -> 14
C6: 45017 | D6: 6 | E6: =E5+D6 -> 22 | F6: 5 | G6: =G5+F6 -> 19
C7: 45047 | D7: 7 | E7: =E6+D7 -> 29 | F7: 7 | G7: =G6+F7 -> 26
C8: 45078 | D8: 7 | E8: =E7+D8 -> 36 | F8: 9 | G8: =G7+F8 -> 35
C9: 45108 | D9: 7 | E9: =E8+D9 -> 43 | F9: 3 | G9: =G8+F9 -> 38 | P9: VENTAS ACUMULADAS
C10: 45139 | E10: =IF(D10="","",D10+E9) | G10: =IF(F10="","",F10+G9) | P10: =G9 -> 38
C11: 45170 | E11: =IF(D11="","",D11+E10) | G11: =IF(F11="","",F11+G10)
C12: 45200 | E12: =IF(D12="","",D12+E11) | G12: =IF(F12="","",F12+G11)
C13: 45231 | E13: =IF(D13="","",D13+E12) | G13: =IF(F13="","",F13+G12)
C14: 45261 | E14: =IF(D14="","",D14+E13) | G14: =IF(F14="","",F14+G13)
D16: % PRESUPUESTO | E16: % PRESUPUESTO ACUMULADO | F16: AVANCE REAL % | G16: AVANCE REAL % ACUMULADO | H16: MONTO PRESUPUESTADO mensual | I16: MONTO PRESUPUESTADO ACUMULADO | J16: MONTO REAL EJECUTADO | K16: MONTO REAL EJECUTADO ACUMULADO
B17: AVANCE DE OBRA | C17: 44927 | D17: 0.04 | E17: =D17 -> 0.04 | F17: 0.03 | G17: =F17 -> 0.03 | H17: 6000000 | I17: =H17 -> 6000000 | J17: 6000000 | K17: =J17 -> 6000000
C18: 44958 | D18: 0.04 | E18: =D18+E17 -> 0.08 | F18: 0.04 | G18: =F18+G17 -> 0.07 | H18: 10000000 | I18: =H18+I17 -> 16000000 | J18: 15000000 | K18: =J18+K17 -> 21000000 | L18: Ejecutado | M18: =G25 -> 0.69
C19: 44986 | D19: 0.06 | E19: =D19+E18 -> 0.14 | F19: 0.05 | G19: =F19+G18 -> 0.12 | H19: 12000000 | I19: =H19+I18 -> 28000000 | J19: 10000000 | K19: =J19+K18 -> 31000000 | L19: Por ejecutar | M19: =1-M18 -> 0.31
C20: 45017 | D20: 0.12 | E20: =D20+E19 -> 0.26 | F20: 0.06 | G20: =F20+G19 -> 0.18 | H20: 24000000 | I20: =H20+I19 -> 52000000 | J20: 24000000 | K20: =J20+K19 -> 55000000
C21: 45047 | D21: 0.12 | E21: =D21+E20 -> 0.38 | F21: 0.1 | G21: =F21+G20 -> 0.28 | H21: 24000000 | I21: =H21+I20 -> 76000000 | J21: 22000000 | K21: =J21+K20 -> 77000000
C22: 45078 | D22: 0.15 | E22: =D22+E21 -> 0.53 | F22: 0.12 | G22: =F22+G21 -> 0.4 | H22: 18000000 | I22: =H22+I21 -> 94000000 | J22: 20000000 | K22: =J22+K21 -> 97000000
C23: 45108 | D23: 0.12 | E23: =IF(D23="","",D23+E22) -> 0.65 | F23: 0.14 | G23: =F23+G22 -> 0.54 | H23: 12000000 | I23: =H23+I22 -> 106000000 | J23: 14000000 | K23: =J23+K22 -> 111000000
C24: 45139 | D24: 0.08 | E24: =IF(D24="","",D24+E23) -> 0.73 | F24: 0.15 | G24: =F24+G23 -> 0.69 | H24: 8000000 | I24: =H24+I23 -> 114000000 | J24: 8500000 | K24: =J24+K23 -> 119500000
C25: 45170 | D25: 0.08 | E25: =IF(D25="","",D25+E24) -> 0.81 | G25: =F25+G24 -> 0.69 | H25: 8000000 | I25: =H25+I24 -> 122000000 | K25: =J25+K24 -> 119500000 | L25: Ejecutado | M25: =K25 -> 119500000
C26: 45200 | D26: 0.08 | E26: =IF(D26="","",D26+E25) -> 0.89 | G26: =F26+G25 -> 0.69 | H26: 6000000 | I26: =H26+I25 -> 128000000 | K26: =J26+K25 -> 119500000 | L26: por ejecutar | M26: =I28-K28 -> 11500000
C27: 45231 | D27: 0.08 | E27: =IF(D27="","",D27+E26) -> 0.97 | G27: =F27+G26 -> 0.69 | H27: 2500000 | I27: =H27+I26 -> 130500000 | K27: =J27+K26 -> 119500000
C28: 45261 | D28: 0.03 | E28: =IF(D28="","",D28+E27) -> 1 | G28: =F28+G27 -> 0.69 | H28: 500000 | I28: =H28+I27 -> 131000000 | K28: =J28+K27 -> 119500000

Sheet ARAYA
E2: VENTAS ESPERADAS | F2: V. ACUMULADAS | G2: VENTAS REALES | H2: VENTAS ACUMULADAS
C3: VENTAS | D3: 45231 | E3: 8 | F3: =E3 -> 8 | G3: 0 | H3: =G3 -> 0 | O3: VENTAS DEL PERIODO
D4: 45261 | E4: 8 | F4: =F3+E4 -> 16 | G4: 0 | H4: =H3+G4 -> 0 | O4: =G9 -> 0
D5: 45292 | E5: 8 | F5: =F4+E5 -> 24 | G5: 0 | H5: =H4+G5 -> 0
D6: 45323 | E6: 12 | F6: =F5+E6 -> 36 | G6: 0 | H6: =H5+G6 -> 0
D7: 45352 | E7: 12 | F7: =F6+E7 -> 48 | G7: 0 | H7: =H6+G7 -> 0
D8: 45383 | E8: 12 | F8: =F7+E8 -> 60 | G8: 0 | H8: =H7+G8 -> 0
D9: 45413 | E9: 12 | F9: =F8+E9 -> 72 | G9: 0 | H9: =H8+G9 -> 0 | O9: VENTAS ACUMULADAS
D10: 45444 | E10: 15 | F10: =IF(E10="","",E10+F9) -> 87 | H10: =IF(G10="","",G10+H9) | O10: =H9 -> 0
D11: 45474 | E11: 15 | F11: =IF(E11="","",E11+F10) -> 102 | H11: =IF(G11="","",G11+H10)
D12: 45505 | E12: 15 | F12: =IF(E12="","",E12+F11) -> 117 | H12: =IF(G12="","",G12+H11)
D13: 45536 | E13: 15 | F13: =IF(E13="","",E13+F12) -> 132 | H13: =IF(G13="","",G13+H12)
D14: 45566 | E14: 15 | F14: =IF(E14="","",E14+F13) -> 147 | H14: =IF(G14="","",G14+H13)
E16: % avance | F16: % AVANCE ACUMULADO | G16: AVANCE REAL % | H16: AVANCE REAL % ACUMULADO | I16: MONTO PRESUPUESTADO mensual | J16: MONTO PRESUPUESTADO ACUMULADO | K16: MONTO REAL EJECUTADO | L16: MONTO REAL EJECUTADO ACUMULADO
C17: AVANCE DE OBRA | D17: 45292 | E17: 0.03 | F17: =E17 -> 0.03 | G17: 0 | H17: =G17 -> 0 | I17: 14678820 | J17: =I17 -> 14678820 | K17: 0 | L17: =K17 -> 0
D18: 45323 | E18: 0.06 | F18: =E18+F17 -> 0.09 | G18: 0 | H18: =G18+H17 -> 0 | I18: 29357640 | J18: =I18+J17 -> 44036460 | K18: 0 | L18: =K18+L17 -> 0 | M18: Ejecutado | N18: =H25 -> 0
D19: 45352 | E19: 0.075 | F19: =E19+F18 -> 0.165 | G19: 0 | H19: =G19+H18 -> 0 | I19: 36697050 | J19: =I19+J18 -> 80733510 | K19: 0 | L19: =K19+L18 -> 0 | M19: Por ejecutar | N19: =1-N18 -> 1
D20: 45383 | E20: 0.11 | F20: =E20+F19 -> 0.275 | G20: 0 | H20: =G20+H19 -> 0 | I20: 53822340 | J20: =I20+J19 -> 134555850 | K20: 0 | L20: =K20+L19 -> 0
D21: 45413 | E21: 0.11 | F21: =E21+F20 -> 0.385 | G21: 0 | H21: =G21+H20 -> 0 | I21: 53822340 | J21: =I21+J20 -> 188378190 | K21: 0 | L21: =K21+L20 -> 0
D22: 45444 | E22: 0.11 | F22: =E22+F21 -> 0.495 | G22: 0 | H22: =G22+H21 -> 0 | I22: 53822340 | J22: =I22+J21 -> 242200530 | K22: 0 | L22: =K22+L21 -> 0
D23: 45474 | E23: 0.11 | F23: =IF(E23="","",E23+F22) -> 0.605 | G23: 0 | H23: =G23+H22 -> 0 | I23: 53822340 | J23: =I23+J22 -> 296022870 | K23: 0 | L23: =K23+L22 -> 0
D24: 45505 | E24: 0.11 | F24: =IF(E24="","",E24+F23) -> 0.715 | G24: 0 | H24: =G24+H23 -> 0 | I24: 53822340 | J24: =I24+J23 -> 349845210 | K24: 0 | L24: =K24+L23 -> 0
D25: 45536 | E25: 0.1 | F25: =IF(E25="","",E25+F24) -> 0.815 | G25: 0 | H25: =G25+H24 -> 0 | I25: 48929400 | J25: =I25+J24 -> 398774610 | K25: 0 | L25: =K25+L24 -> 0 | M25: Ejecutado | N25: =L25 -> 0
D26: 45566 | E26: 0.085 | F26: =IF(E26="","",E26+F25) -> 0.9 | G26: 0 | H26: =G26+H25 -> 0 | I26: 41589990 | J26: =I26+J25 -> 440364600 | K26: 0 | L26: =K26+L25 -> 0 | M26: por ejecutar | N26: =J28-L28 -> 522076698
D27: 45597 | E27: 0.042 | F27: =IF(E27="","",E27+F26) -> 0.942 | G27: 0 | H27: =G27+H26 -> 0 | I27: 35229168 | J27: =I27+J26 -> 475593768 | K27: 0 | L27: =K27+L26 -> 0
D28: 45627 | E28: 0.035 | F28: =IF(E28="","",E28+F27) -> 0.977 | G28: 0 | H28: =G28+H27 -> 0 | I28: 46482930 | J28: =I28+J27 -> 522076698 | K28: 0 | L28: =K28+L27 -> 0
D29: 45658 | E29: 0.023 | F29: =IF(E29="","",E29+F28) -> 1 | G29: 0 | H29: =G29+H28 -> 0 | I29: 47950812 | J29: =I29+J28 -> 570027510 | K29: 0 | L29: 0
F30: =IF(E30="","",E30+F29)
B32: ADI
B34: B.- COSTOS DEL PROYECTO | F34: AVANCE EN DOP | I34: ACUMULADO | J34: PRESUPUESTO A LA FECHA | K34: % CUMPLIMIENTO | L34: % AVANCE EN DOP DEL TOTAL | M34: TENDENCIA
B35: PARTIDA | D35: DOP | E35: US $ | F35: 45047 | G35: 45078 | H35: 45108 | K35: Mes Actual
B36: Terreno | D36: 98128296 | E36: 1752291 | K36: =IFERROR(I36/J36,"")
A37: Etapa 1 462 | B37: Costo Urbanismo | D37: 236811000 | E37: 4228767.9 | I37: =SUM(F37:H37) -> 0 | J37: 0 | K37: =IFERROR(I37/J37,"") | L37: =IF((I37/D37)=0,"",(I37/D37))
B38: Micro Urbanismo | D38: 193611000 | E38: 3457339.3 | I38: =SUM(F38:H38) -> 0 | J38: 0 | K38: =IFERROR(I38/J38,"") | L38: =IF((I38/D38)=0,"",(I38/D38))
B39: Macro Urbanismo | D39: 43200000 | E39: 771428.57 | I39: =SUM(F39:H39) -> 0 | J39: 0 | K39: =IFERROR(I39/J39,"") | L39: =IF((I39/D39)=0,"",(I39/D39))
B40: Costo Vivienda | D40: 1123200000 | E40: 20057143 | I40: =SUM(F40:H40) -> 0 | J40: 0 | K40: =IFERROR(I40/J40,"") | L40: =IF((I40/D40)=0,"",(I40/D40))
B41: Gerencia Contrucción: | D41: 163201320 | E41: 2914309.3 | I41: =SUM(F41:H41) -> 0 | J41: 1500000 | K41: =IFERROR(I41/J41,"") -> 0 | L41: =IF((I41/D41)=0,"",(I41/D41))
B42: Indirectos de Obra | D42: 27200220 | E42: 485718.21 | I42: =SUM(F42:H42) -> 0 | J42: 2408610 | K42: =IFERROR(I42/J42,"") -> 0 | L42: =IF((I42/D42)=0,"",(I42/D42))
B43: Total Costos Construcción | D43: =D37+D40+D41+D42 -> 1550412540 | E43: =E37+E40+E41+E42 -> 27685938 | F43: =SUM(F37:F42) -> 0 | G43: =SUM(G37:G42) -> 0 | H43: =SUM(H37:H42) -> 0 | I43: =SUM(I37:I42) -> 0 | J43: =SUM(J37:J42) -> 3908610 | K43: =IFERROR(I43/J43,"") -> 0 | L43: =IF((I43/D43)=0,"",(I43/D43))
B44: Gerencia de la Promotora | D44: 163201320 | E44: 2914309.3 | I44: =SUM(F44:H44) -> 0 | J44: 1500000 | K44: =IFERROR(I44/J44,"") -> 0 | L44: =IF((I44/D44)=0,"",(I44/D44))
...

Sheet budget (6)
A1: D1 | B1: D2 | C1: D2 | D1: PRESUPUESTO ORIGINAL | E1: COMPROMETIDOS | F1: COSTO DE TRABAJO A LA FECHA | G1: COSTO PROYECTADO A LA FECHA | H1: PRECIO UNITARIO DEL PRESUPUESTO | I1: PROYECCIÓN PARA TERMINAR | J1: COSTO TERMINADO AL TERMINAR | K1: PROYECTADO ARRIBA ABAJO DEL PRESUPUESTO
A2: 1 - CONSTRUCCION | B2: 1-1 - TERRENO | C2: 1-1-1 - TERRENO ADI | D2: 7172000.3 | E2: 0 | F2: 0 | G2: 0 | H2: 7172000.3 | I2: 7172000.3 | J2: 7172000.3 | K2: 0
A3: 1 - CONSTRUCCION | B3: 1-1 - TERRENO | C3: 1-1-2 - COSTO ASOCIADO TERRENO | D3: 96213169 | E3: 96213169 | F3: 96213169 | G3: 96213169 | H3: 96213169 | I3: 0 | J3: 96213169 | K3: 0
A4: 1 - CONSTRUCCION | B4: 1-2 - DISEÑO Y PROYECTO | C4: 1-2-1 - DISEÑO Y PROYECTO ADI | D4: -1132808.6 | E4: 0 | F4: 0 | G4: 0 | H4: -1132808.6 | I4: 0 | J4: 0 | K4: -1132808.6
A5: 1 - CONSTRUCCION | B5: 1-2 - DISEÑO Y PROYECTO | C5: 1-2-2 - ESTUDIOS | D5: 5641221.5 | E5: 5641221.5 | F5: 0 | G5: 5641221.5 | H5: 5641221.5 | I5: 0 | J5: 5641221.5 | K5: 0
A6: 1 - CONSTRUCCION | B6: 1-2 - DISEÑO Y PROYECTO | C6: 1-2-3 - DISEÑO Y ARQUITECTURA | D6: 8804294.6 | E6: 8604294.6 | F6: 10000 | G6: 8604294.6 | H6: 8804294.6 | I6: 200000 | J6: 8804294.6 | K6: 0
A7: 1 - CONSTRUCCION | B7: 1-2 - DISEÑO Y PROYECTO | C7: 1-2-4 - INGENIERIAS | D7: 5954647.6 | E7: 5932855.3 | F7: 0 | G7: 5932855.3 | H7: 5954647.6 | I7: 21792.24 | J7: 5954647.6 | K7: 0
A8: 1 - CONSTRUCCION | B8: 1-2 - DISEÑO Y PROYECTO | C8: 1-2-5 - COMPUTOS | D8: 367644.95 | E8: 367644.95 | F8: 0 | G8: 367644.95 | H8: 367644.95 | I8: 0 | J8: 367644.95 | K8: 0
A9: 1 - CONSTRUCCION | B9: 1-3 - PRELIMINARES DE OBRA | C9: 1-3-1 - PRELIMINARES DE OBRA ADI | D9: 2608628.3 | E9: 0 | F9: 0 | G9: 0 | H9: 2608628.3 | I9: 2608628.3 | J9: 2608628.3 | K9: 0
A10: 1 - CONSTRUCCION | B10: 1-3 - PRELIMINARES DE OBRA | C10: 1-3-2 - OBRAS PRELIMINARES AREA CAMPAMENTO | D10: 1897166 | E10: 1897166 | F10: 0 | G10: 1897166 | H10: 1897166 | I10: 0 | J10: 1897166 | K10: 0
A11: 1 - CONSTRUCCION | B11: 1-3 - PRELIMINARES DE OBRA | C11: 1-3-3 - OBRAS PRELIMINARES AREA SHOWROOM | D11: 7141349 | E11: 7141349 | F11: 0 | G11: 7141349 | H11: 7141349 | I11: 0 | J11: 7141349 | K11: 0
A12: 1 - CONSTRUCCION | B12: 1-4 - URBANISMO | C12: 1-4-1 - URBANISMO ADI | D12: 11803487 | E12: 0 | F12: 0 | G12: 0 | H12: 11803487 | I12: 11803487 | J12: 11803487 | K12: 0
A13: 1 - CONSTRUCCION | B13: 1-4 - URBANISMO | C13: 1-4-2 - MOVIMIENTO DE TIERRA | D13: 54584720 | E13: 0 | F13: 0 | G13: 0 | H13: 54584720 | I13: 54584720 | J13: 54584720 | K13: 0
... A48: 2 - OPERATIVO | B48: 2-4 - PUBLICIDAD Y PROMOCION | C48: 2-4-1 - PUBLICIDAD Y PROMOCION ADI | D48: 50231089 | E48: 3786501.9 | F48: 0 | G48: 3786501.9 | H48: 50231089 | I48: 46444587 | J48: 50231089 | K48: 0
A49: 2 - OPERATIVO | B49: 2-4 - PUBLICIDAD Y PROMOCION | C49: 2-4-2 - PUBLICIDAD Y PROMOCION | F49: 390000 | G49: 1300000 | H49: 1300000 | I49: 0 | J49: 1300000 | K49: 0 | L49: ESTA DUPLICADO
A50: 2 - OPERATIVO | B50: 2-5 - POST-VENTAS | C50: 2-5-1 - POST-VENTAS ADI | D50: 19238273 | E50: 0 | F50: 0 | G50: 0 | H50: 19238273 | I50: 19238273 | J50: 19238273 | K50: 0
A51: 2 - OPERATIVO | B51: 2-5 - POST-VENTAS | C51: 2-5-2 - POST-VENTAS | D51: 0 | E51: 0 | F51: 0 | G51: 0 | H51: 0 | I51: 0 | J51: 0 | K51: 0
A52: 3 - OTROS | B52: 3-1 - PERMISOS, LEGALES Y PRELIMINARES | C52: 3-1-1 - PERMISOS,LEGALES Y PRELIMINARES ADI | D52: 11603049 | E52: 0 | F52: 0 | G52: 0 | H52: 11603049 | I52: 11603049 | J52: 11603049 | K52: 0
A53: 3 - OTROS | B53: 3-1 - PERMISOS, LEGALES Y PRELIMINARES | C53: 3-1-2 - PERMISOS,LEGALES Y PRELIMINARES | D53: 3396950.7 | E53: 3396950.7 | F53: 0 | G53: 3396950.7 | H53: 3396950.7 | I53: 0 | J53: 3396950.7 | K53: 0
A54: 3 - OTROS | B54: 3-2 - IMPREVISTOS | C54: 3-2-1 - IMPREVISTOS ADI | D54: 19238273 | E54: 0 | F54: 0 | G54: 0 | H54: 19238273 | I54: 19238273 | J54: 19238273 | K54: 0
A55: 3 - OTROS | B55: 3-2 - IMPREVISTOS | C55: 3-2-2 - IMPREVISTOS | D55: 0 | E55: 0 | F55: 0 | G55: 0 | H55: 0 | I55: 0 | J55: 0 | K55: 0
A56: 3 - OTROS | B56: 3-3 - GASTOS FINANCIEROS | C56: 3-3-1 - GASTOS FINANCIEROS ADI | D56: 173144460 | E56: 0 | F56: 0 | G56: 0 | H56: 173144460 | I56: 173144460 | J56: 173144460 | K56: 0
A57: 3 - OTROS | B57: 3-3 - GASTOS FINANCIEROS | C57: 3-3-2 - GASTOS FINANCIEROS | D57: 0 | E57: 0 | F57: 0 | G57: 0 | H57: 0 | I57: 0 | J57: 0 | K57: 0
D58: =SUM(D2:D57) -> 2803282274 | E58: =SUM(E2:E57) -> 1.3298115e+08 | F58: =SUM(F2:F57) -> 96613169 | G58: =SUM(G2:G57) -> 1.3428115e+08 | H58: =SUM(H2:H57) -> 2804582274 | I58: =SUM(I2:I57) -> 2.6714339e+09 | J58: =SUM(J2:J57) -> 2.8057151e+09 | K58: =SUM(K2:K57) -> -1132808.6

Sheet PRESENTACIÓN MARZO 24
I2: pagos | J2: contratos | L2: pendiente de pagar
B3: PRESUPUESTO A MARZO 2024 | E3: 59.1 | F3: COSTO A LA FECHA | I3: TOTAL A LA FECHA | J3: COMPROMETIDO | K3: PROYECTADO PARA TERMINAR | L3: POR EJECUTAR
B4: PARTIDA | D4: DOP | E4: US $ | F4: 45292 | G4: 45323 | H4: 45352
B5: Terreno | D5: =SUM('budget (6)'!D2:D3) -> 103385169 | E5: =D5/E3 -> 1749326 | I5: =SUM('budget (6)'!F2:F3) -> 96213169 | J5: =SUM('budget (6)'!E2:E3) -> 96213169 | K5: =SUM('budget (6)'!J2:J3) -> 103385169 | L5: =J5-I5 -> 0
B6: Costo Urbanismo | D6: =SUM('budget (6)'!D9:D22) -> 4.5174906e+08 | E6: =D6/$E$3 -> 7643808.1 | I6: =9038515 -> 9038515 | J6: =SUM('budget (6)'!E9:E22) -> 9038515 | K6: =SUM('budget (6)'!J9:J22) -> 4.5174906e+08 | L6: =J6-I6 -> 0
B7: Costo Vivienda | D7: =SUM('budget (6)'!D23:D36) -> 1265953920 | E7: =D7/$E$3 -> 21420540 | I7: =SUM('budget (6)'!F23:F36) -> 0 | J7: =SUM('budget (6)'!E23:E36) -> 0 | K7: =SUM('budget (6)'!J23:J36) -> 1265953920 | L7: =J7-I7 -> 0
B8: Gerencia Construcción: | D8: =SUM('budget (6)'!D37:D38) -> 171770298 | E8: =D8/$E$3 -> 2906434.8 | I8: =SUM('budget (6)'!F37:F38) -> 0 | J8: =SUM('budget (6)'!E37:E38) -> 0 | K8: =SUM('budget (6)'!J37:J38) -> 171770298 | L8: =J8-I8 -> 0
B9: Indirectos de Obra | D9: ='budget (6)'!D39+'budget (6)'!D40 -> 34354060 | E9: =D9/$E$3 -> 581286.97 | I9: ='budget (6)'!F39+'budget (6)'!F40 -> 0 | J9: ='budget (6)'!E39+'budget (6)'!E40 -> 0 | K9: ='budget (6)'!J39+'budget (6)'!J40 -> 34354060 | L9: =J9-I9 -> 0
B10: Total Costos Construcción | D10: =SUM(D6:D9) -> 1923827338 | E10: =SUM(E6:E9) -> 32552070 | I10: =SUM(I6:I9) -> 9038515 | J10: =SUM(J6:J9) -> 9038515 | K10: =SUM(K6:K9) -> 1923827338 | L10: =J10-I10 -> 0
B11: Gerencia de la Promotora | D11: =SUM('budget (6)'!D41:D42) -> 137416238 | E11: =D11/$E$3 -> 2325147.9 | I11: =SUM('budget (6)'!F41:F42) -> 0 | J11: =SUM('budget (6)'!E41:E42) -> 0 | K11: =SUM('budget (6)'!J41:J42) -> 137416238 | L11: =J11-I11 -> 0
B12: Gerencia de Ventas | D12: =SUM('budget (6)'!D43:D45) -> 274832477 | E12: =D12/$E$3 -> 4650295.7 | I12: =SUM('budget (6)'!F43:F45) -> 0 | J12: =SUM('budget (6)'!E43:E45) -> 0 | K12: =SUM('budget (6)'!J43:J45) -> 274832477 | L12: =J12-I12 -> 0
B13: Administración Fiducia | D13: =SUM('budget (6)'!D46:D47) -> 67333957 | E13: =D13/$E$3 -> 1139322.5 | I13: =SUM('budget (6)'!F46:F47) -> 0 | J13: =SUM('budget (6)'!E46:E47) -> 0 | K13: =SUM('budget (6)'!J46:J47) -> 67333957 | L13: =J13-I13 -> 0
B14: Publicidad | D14: =SUM('budget (6)'!D48:D49) -> 50231089 | E14: =D14/$E$3 -> 849933.82 | I14: =446334.38 -> 446334.38 | J14: =SUM('budget (6)'!E48) -> 3786501.9 | K14: 50231089 | L14: =J14-I14 -> 3340167.5
B15: Post Ventas | D15: =SUM('budget (6)'!D50:D51) -> 19238273 | E15: =D15/$E$3 -> 325520.69 | I15: 0 | J15: =SUM('budget (6)'!E50:E51) -> 0 | K15: =SUM('budget (6)'!J50:J51) -> 19238273 | L15: =J15-I15 -> 0
B16: Total Gastos Operativos | D16: =SUM(D11:D15) -> 549052034 | E16: =SUM(E11:E15) -> 9290220.5 | I16: =SUM(I11:I15) -> 446334.38 | J16: =SUM(J11:J15) -> 3786501.9 | K16: =SUM(K11:K15) -> 549052034 | L16: =J16-I16 -> 3340167.5 | N16: PERMISOS | O16: REE,BOLSO BAK
B17: Permisos legales y Preliminares | D17: =SUM('budget (6)'!D52:D53) -> 15000000 | E17: =D17/$E$3 -> 253807.11 | I17: 1576990 | J17: =N17+I17+O17 -> 13841815 | K17: =SUM('budget (6)'!J52:J53) -> 15000000 | L17: =J17-I17 -> 12264825 | N17: 11255347 | O17: 1009477.8
A18: MODIFICAR ADI 22,000,000 | B18: Diseño y Proyecto | D18: 22000000 | E18: =D18/$E$3 -> 372250.42 | I18: =12246486.57 -> 12246487 | J18: =SUM('budget (6)'!E4:E8) -> 20546016 | K18: 22000000 | L18: =J18-I18 -> 8299529.8
B19: Gastos Financieros | D19: ='budget (6)'!D56+'budget (6)'!D57 -> 173144460 | E19: =D19/$E$3 -> 2929686.3 | I19: ='budget (6)'!F56+'budget (6)'!F57 -> 0 | J19: ='budget (6)'!E56+'budget (6)'!E57 -> 0 | K19: ='budget (6)'!J56+'budget (6)'!J57 -> 173144460 | L19: =J19-I19 -> 0
B20: Imprevistos | D20: ='budget (6)'!D54+'budget (6)'!D55 -> 19238273 | E20: =D20/$E$3 -> 325520.69 | I20: ='budget (6)'!F54+'budget (6)'!F55 -> 0 | J20: ='budget (6)'!E54+'budget (6)'!E55 -> 0 | K20: ='budget (6)'!J54+'budget (6)'!J55 -> 19238273 | L20: =J20-I20 -> 0
B21: Total Otros Gastos | D21: =SUM(D17:D20) -> 229382733 | E21: =SUM(E17:E20) -> 3881264.5 | I21: =SUM(I17:I20) -> 13823477 | J21: =SUM(J17:J20) -> 34387831 | K21: =SUM(K17:K20) -> 229382733 | L21: =J21-I21 -> 20564355
B22: Costos Totales de Proyecto | D22: =D5+D10+D16+D21 -> 2805647274 | E22: =E5+E10+E16+E21 -> 47472881 | F22: =F21+F16+F10+F5 -> 0 | G22: =G21+G16+G10+G5 -> 0 | H22: =H21+H16+H10+H5 -> 0 | I22: =I21+I16+I10+I5 -> 1.1952149e+08 | J22: =J21+J16+J10+J5 -> 1.4342602e+08 | K22: =K21+K16+K10+K5 -> 2805647274 | L22: =J22-I22 -> 23904522
I25: ADELANTO AFI | J25: 160000000 | L25: =J26/J25 -> 0.8964126
I26: Gastado y comprometido | J26: =J22 -> 1.4342602e+08
E27: =J27-SUM(I35:I38) -> 1500000 | I27: Disponible | J27: =J25-J26 -> 16573983
E29: PARTIDA | I29: MES 1 | J29: MES 2 | K29: MES 3 | L29: MES 4 | M29: MES 5 | N29: MES 6 | O29: MES 7 | P29: MES 8 | Q29: MES 9 | R29: Total
E30: gerencias | I30: 1000000 | J30: 1000000 | K30: 1000000 | L30: 1000000 | M30: 1000000 | N30: 1000000 | O30: 1000000 | P30: 1000000 | Q30: 1000000 | R30: =SUM(I30:Q30) -> 9000000
E31: promocion | I31: 500000 | J31: 500000 | K31: 500000 | L31: 500000 | M31: 500000 | N31: 500000 | O31: 500000 | P31: 500000 | Q31: 500000 | R31: =SUM(I31:Q31) -> 4500000
E32: atención al cliente | L32: 350000 | M32: 350000 | N32: 350000 | O32: 350000 | P32: 350000 | Q32: 350000 | R32: =SUM(I32:Q32) -> 2100000
I33: =SUM(I30:I32) -> 1500000 | J33: =SUM(J30:J32) -> 1500000 | K33: =SUM(K30:K32) -> 1500000 | L33: =SUM(L30:L32) -> 1850000 | M33: =SUM(M30:M32) -> 1850000 | N33: =SUM(N30:N32) -> 1850000 | O33: =SUM(O30:O32) -> 1850000 | P33: =SUM(P30:P32) -> 1850000 | Q33: =SUM(Q30:Q32) -> 1850000
E34: Acumulado | J34: =I33+J33 -> 3000000 | K34: =J33+J34 -> 4500000 | L34: =K33+K34 -> 6000000 | M34: =L33+L34 -> 7850000 | N34: =M33+M34 -> 9700000 | O34: =N33+N34 -> 11550000 | P34: =O33+O34 -> 13400000 | Q34: =P33+P34 -> 15250000
E36: Disponible | I36: =$J$27-I33 -> 15073983 | J36: =$J$27-J34 -> 13573983 | K36: =$J$27-K34 -> 12073983 | L36: =$J$27-L34 -> 10573983 | M36: =$J$27-M34 -> 8723983.2 | N36: =$J$27-N34 -> 6873983.2 | O36: =$J$27-O34 -> 5023983.2 | P36: =$J$27-P34 -> 3173983.2 | Q36: =$J$27-Q34 -> 1323983.2

Sheet budget (8)
A1: Código de Costo Nivel 1 | B1: Código de Costo Nivel 2 | C1: Código de Costo Nivel 3 | D1: Presupuesto Original | E1: Costos Comprometidos (CONTRATO) | F1: Costos de Trabajo a la Fecha (CUBICADO) | G1: Costos Proyectados | H1: Precio unitario del presupuesto | I1: Proyección para terminar | J1: Costo Estimado al Terminar | K1: Proyectado Arriba/Abajo del Presupuesto
A2: 1 - CONSTRUCCION | B2: 1-1 - TERRENO | C2: 1-1-1 - TERRENO ADI | D2: 7172000.3 | E2: 0 | F2: 0 | G2: 0 | H2: 7172000.3 | I2: 7172000.3 | J2: 7172000.3 | K2: 0
A3: 1 - CONSTRUCCION | B3: 1-1 - TERRENO | C3: 1-1-2 - COSTO ASOCIADO TERRENO | D3: 96213169 | E3: 96272169 | F3: 96272169 | G3: 96272169 | H3: 96213169 | I3: 0 | J3: 96272169 | K3: -59000
A4: 1 - CONSTRUCCION | B4: 1-2 - DISEÑO Y PROYECTO | C4: 1-2-1 - DISEÑO Y PROYECTO ADI | D4: 22191.38 | E4: 0 | F4: 0 | G4: 0 | H4: 22191.38 | I4: 22191.38 | J4: 22191.38 | K4: 0
A5: 1 - CONSTRUCCION | B5: 1-2 - DISEÑO Y PROYECTO | C5: 1-2-2 - ESTUDIOS | D5: 0 | E5: 0 | F5: 0 | G5: 0 | H5: 0
A6: 1 - CONSTRUCCION | B6: 1-2 - DISEÑO Y PROYECTO | C6: 1-2-2 - ESTUDIOS | D6: 5641221.5 | E6: 5641221.5 | F6: 0 | G6: 5641221.5 | H6: 5641221.5 | I6: 0 | J6: 5641221.5 | K6: 0
A7: 1 - CONSTRUCCION | B7: 1-2 - DISEÑO Y PROYECTO | C7: 1-2-3 - DISEÑO Y ARQUITECTURA | D7: 8804294.6 | E7: 8785614.6 | F7: 0 | G7: 8785614.6 | H7: 8804294.6 | I7: 18680.02 | J7: 8804294.6 | K7: 0
A8: 1 - CONSTRUCCION | B8: 1-2 - DISEÑO Y PROYECTO | C8: 1-2-4 - INGENIERIAS | D8: 5954647.6 | E8: 5932855.3 | F8: 0 | G8: 5932855.3 | H8: 5954647.6 | I8: 21792.24 | J8: 5954647.6 | K8: 0
A9: 1 - CONSTRUCCION | B9: 1-2 - DISEÑO Y PROYECTO | C9: 1-2-5 - COMPUTOS | D9: 367644.95 | E9: 367644.95 | F9: 0 | G9: 367644.95 | H9: 367644.95 | I9: 0 | J9: 367644.95 | K9: 0
A10: 1 - CONSTRUCCION | B10: 1-3 - PRELIMINARES DE OBRA | C10: 1-3-1 - PRELIMINARES DE OBRA ADI | D10: 2608628.3 | E10: 0 | F10: 0 | G10: 0 | H10: 2608628.3 | I10: 2608628.3 | J10: 2608628.3 | K10: 0
A11: 1 - CONSTRUCCION | B11: 1-3 - PRELIMINARES DE OBRA | C11: 1-3-2 - OBRAS PRELIMINARES AREA CAMPAMENTO | D11: 1897166.4 | E11: 1897166.4 | F11: 480315 | G11: 1897166.4 | H11: 1897166.4 | I11: 0 | J11: 1897166.4 | K11: 0
A12: 1 - CONSTRUCCION | B12: 1-3 - PRELIMINARES DE OBRA | C12: 1-3-3 - OBRAS PRELIMINARES AREA SHOWROOM | D12: 7141349 | E12: 7141349 | F12: 1209931.5 | G12: 7141349 | H12: 7141349 | I12: 0 | J12: 7141349 | K12: 0
A13: 1 - CONSTRUCCION | B13: 1-4 - URBANISMO | C13: 1-4-1 - URBANISMO ADI | D13: 11813427 | E13: 0 | F13: 0 | G13: 0 | H13: 11813427 | I13: 11813427 | J13: 11813427 | K13: 0
A14: 1 - CONSTRUCCION | B14: 1-4 - URBANISMO | C14: 1-4-2 - MOVIMIENTO DE TIERRA | D14: 54584720 | E14: 0 | F14: 0 | G14: 0 | H14: 54584720 | I14: 54584720 | J14: 54584720 | K14: 0
A15: 1 - CONSTRUCCION | B15: 1-4 - URBANISMO | C15: 1-4-3 - HIDROSANITARIAS | D15: 56232241 | E15: 0 | F15: 0 | G15: 0 | H15: 56232241 | I15: 56232241 | J15: 56232241 | K15: 0
A16: 1 - CONSTRUCCION | B16: 1-4 - URBANISMO | C16: 1-4-4 - SISTEMAS DE AGUAS | D16: 35679323 | E16: 0 | F16: 0 | G16: 0 | H16: 35679323 | I16: 35679323 | J16: 35679323 | K16: 0
A17: 1 - CONSTRUCCION | B17: 1-4 - URBANISMO | C17: 1-4-6 - INFRAESTRUCTURA ELECTRICA | D17: 1.3513803e+08 | E17: 0 | F17: 0 | G17: 0 | H17: 1.3513803e+08 | I17: 1.3513803e+08 | J17: 1.3513803e+08 | K17: 0
... A26: 1 - CONSTRUCCION | B26: 1-5 - EDIFICACIONES | C26: 1-5-3 - SUPERESTRUCTURA | D26: 2.8304295e+08 | E26: 0 | F26: 0 | G26: 0 | H26: 2.8304295e+08 | I26: 2.8304295e+08 | J26: 2.8304295e+08 | K26: 0
A27: 1 - CONSTRUCCION | B27: 1-5 - EDIFICACIONES | C27: 1-5-4 - INSTALACIONES ELECTRICAS | D27: 0 | E27: 0 | F27: 0 | G27: 0 | H27: 0
A28: 1 - CONSTRUCCION | B28: 1-5 - EDIFICACIONES | C28: 1-5-4 - INSTALACIONES ELECTRICAS | D28: 60439200 | E28: 0 | F28: 0 | G28: 0 | H28: 60439200 | I28: 60439200 | J28: 60439200 | K28: 0
A29: 1 - CONSTRUCCION | B29: 1-5 - EDIFICACIONES | C29: 1-5-5 - TELECOMUNICACIONES | D29: 8446912.3 | E29: 0 | F29: 0 | G29: 0 | H29: 8446912.3 | I29: 8446912.3 | J29: 8446912.3 | K29: 0
A30: 1 - CONSTRUCCION | B30: 1-5 - EDIFICACIONES | C30: 1-5-6 - INSTALACIONES SANITARIAS | D30: 1.0100749e+08 | E30: 0 | F30: 0 | G30: 0 | H30: 1.0100749e+08 | I30: 1.0100749e+08 | J30: 1.0100749e+08 | K30: 0
A31: 1 - CONSTRUCCION | B31: 1-5 - EDIFICACIONES | C31: 1-5-7 - INSTALACIONES MECANICAS | D31: 455797.65 | E31: 0 | F31: 0 | G31: 0 | H31: 455797.65 | I31: 455797.65 | J31: 455797.65 | K31: 0
A32: 1 - CONSTRUCCION | B32: 1-5 - EDIFICACIONES | C32: 1-5-8 - ALBANILERIA | D32: 79619986 | E32: 0 | F32: 0 | G32: 0 | H32: 79619986 | I32: 79619986 | J32: 79619986 | K32: 0
A33: 1 - CONSTRUCCION | B33: 1-5 - EDIFICACIONES | C33: 1-5-9 - HERRERIA | D33: 55148949 | E33: 0 | F33: 0 | G33: 0 | H33: 55148949 | I33: 55148949 | J33: 55148949 | K33: 0
A34: 1 - CONSTRUCCION | B34: 1-5 - EDIFICACIONES | C34: 1-5-10 - REVESTIMIENTO | D34: 1.7979257e+08 | E34: 0 | F34: 0 | G34: 0 | H34: 1.7979257e+08 | I34: 1.7979257e+08 | J34: 1.7979257e+08 | K34: 0
A35: 1 - CONSTRUCCION | B35: 1-5 - EDIFICACIONES | C35: 1-5-11 - CARPINTERIA | D35: 1.1340591e+08 | E35: 0 | F35: 0 | G35: 0 | H35: 1.1340591e+08 | I35: 1.1340591e+08 | J35: 1.1340591e+08 | K35: 0
A36: 1 - CONSTRUCCION | B36: 1-5 - EDIFICACIONES | C36: 1-5-12 - VENTANERIA | D36: 95070320 | E36: 0 | F36: 0 | G36: 0 | H36: 95070320 | I36: 95070320 | J36: 95070320 | K36: 0
A37: 1 - CONSTRUCCION | B37: 1-5 - EDIFICACIONES | C37: 1-5-13 - PINTURA | D37: 1.2190433e+08 | E37: 0 | F37: 0 | G37: 0 | H37: 1.2190433e+08 | I37: 1.2190433e+08 | J37: 1.2190433e+08 | K37: 0
A38: 1 - CONSTRUCCION | B38: 1-5 - EDIFICACIONES | C38: 1-5-14 - MISCELANEOS | D38: 74569125 | E38: 0 | F38: 0 | G38: 0 | H38: 74569125 | I38: 74569125 | J38: 74569125 | K38: 0
A39: 1 - CONSTRUCCION | B39: 1-6 - GERENCIA DE CONSTRUCCION | C39: 1-6-1 - GERENCIA DE CONSTRUCCION ADI | D39: 171771292 | E39: 0 | F39: 0 | G39: 0 | H39: 171771292 | I39: 171771292 | J39: 171771292 | K39: 0
... A59: 3 - OTROS | B59: 3-3 - GASTOS FINANCIEROS | C59: 3-3-2 - GASTOS FINANCIEROS | D59: 0 | E59: 0 | F59: 0 | G59: 0 | H59: 0 | I59: 0 | J59: 0 | K59: 0
D60: =SUM(D2:D59) -> 2831861943 | E60: =SUM(E2:E59) -> 2.7193771e+08 | F60: =SUM(F2:F59) -> 98352415 | G60: =SUM(G2:G59) -> 2.7193771e+08 | H60: =SUM(H2:H59) -> 2831861943 | I60: =SUM(I2:I59) -> 2.5599832e+09 | J60: =SUM(J2:J59) -> 2831920943 | K60: =SUM(K2:K59) -> -59000
D62: 2816861943 | E62: 2.6724076e+08 | F62: 98832094 | G62: 2.6724076e+08 | H62: 2816861943 | I62: 2.5496802e+09 | J62: 2816920943 | K62: -59000
D63: Presupuesto Original | E63: Costos Comprometidos | F63: Costos de Trabajo a la Fecha | G63: Costos Proyectados | H63: Precio unitario del presupuesto | I63: Proyección para terminar | J63: Costo Estimado al Terminar | K63: Proyectado Arriba/Abajo del Presupuesto
D64: =D1 -> Presupuesto Original | E64: =E1 -> Costos Comprometidos (CONTRATO) | F64: =F1 -> Costos de Trabajo a la Fecha (CUBICADO) | G64: =G1 -> Costos Proyectados | H64: =H1 -> Precio unitario del presupuesto | I64: =I1 -> Proyección para terminar | J64: =J1 -> Costo Estimado al Terminar | K64: =K1 -> Proyectado Arriba/Abajo del Presupuesto
D65: =D60-D62 -> 15000000 | E65: =E60-E62 -> 4696950.7 | F65: =F60-F62 -> -479678.33 | G65: =G60-G62 -> 4696950.7 | H65: =H60-H62 -> 15000000 | I65: =I60-I62 -> 10303049 | J65: =J60-J62 -> 15000000 | K65: =K60-K62 -> 0

Sheet PRESENTACIÓN ABRIL 24 v0
J1: IMAGEN DEL ADI archivo : Flujo_de_caja_PUNTA_CANA_462_MAR2024_V.0.XLSX al 02/05/24
E2: TC al 7 de mayo
B3: PRESUPUESTO ABRIL 2024 | E3: 59.15 | F3: TOTAL EJECUTADO | G3: COMPROMETIDO | H3: PROYECTADO PARA TERMINAR | I3: POR EJECUTAR
B4: PARTIDA | D4: DOP | E4: US $
B5: Terreno | D5: =SUM('budget (8)'!D2:D3) -> 103385169 | E5: =D5/E3 -> 1747847.3 | F5: =SUM('budget (8)'!F2:F3) -> 96272169 | G5: =SUM('budget (8)'!E2:E3) -> 96272169 | H5: =SUM('budget (8)'!J2:J3) -> 103444169 | I5: =G5-F5 -> 0
B6: Costo Urbanismo | D6: =SUM('budget (8)'!D10:D23) -> 4.51759e+08 | E6: =D6/$E$3 -> 7637514.8 | F6: =SUM('budget (8)'!F10:F23) -> 1690246.5 | G6: =SUM('budget (8)'!E10:E23) -> 9038515.4 | H6: =SUM('budget (8)'!J10:J23) -> 4.51759e+08 | I6: =G6-F6 -> 7348268.9
B7: Costo Vivienda | D7: =SUM('budget (8)'!D24:D38) -> 1265953920 | E7: =D7/$E$3 -> 21402433 | F7: =SUM('budget (8)'!F24:F38) -> 0 | G7: =SUM('budget (8)'!E24:E38) -> 0 | H7: =SUM('budget (8)'!J24:J38) -> 1265953920 | I7: =G7-F7 -> 0
B8: Gerencia Construcción: | D8: =SUM('budget (8)'!D39:D40) -> 171771292 | E8: =D8/$E$3 -> 2903994.8 | F8: =SUM('budget (8)'!F39:F40) -> 0 | G8: =SUM('budget (8)'!E39:E40) -> 0 | H8: =SUM('budget (8)'!J39:J40) -> 171771292 | I8: =G8-F8 -> 0
B9: Indirectos de Obra | D9: =SUM('budget (8)'!D41:D42) -> 34354258 | E9: =D9/$E$3 -> 580798.95 | F9: =SUM('budget (8)'!F41:F42) -> 0 | G9: =SUM('budget (8)'!E41:E42) -> 0 | H9: =SUM('budget (8)'!J41:J42) -> 34354258 | I9: =G9-F9 -> 0
B10: Total Costos Construcción | D10: =SUM(D6:D9) -> 1923838470 | E10: =SUM(E6:E9) -> 32524742 | F10: =SUM(F6:F9) -> 1690246.5 | G10: =SUM(G6:G9) -> 9038515.4 | H10: =SUM(H6:H9) -> 1923838470 | I10: =G10-F10 -> 7348268.9
B11: Gerencia de la Promotora | D11: =SUM('budget (8)'!D43:D44) -> 137417034 | E11: =D11/$E$3 -> 2323195.8 | F11: =SUM('budget (8)'!F43:F44) -> 0 | G11: =SUM('budget (8)'!E43:E44) -> 137416238 | H11: =SUM('budget (8)'!J43:J44) -> 137417034 | I11: =G11-F11 -> 137416238
B12: Gerencia de Ventas | D12: =SUM('budget (8)'!D45:D47) -> 281704919 | E12: =D12/$E$3 -> 4762551.5 | F12: =SUM('budget (8)'!F45:F47) -> 0 | G12: =SUM('budget (8)'!E45:E47) -> 0 | H12: =SUM('budget (8)'!J45:J47) -> 281704919 | I12: =G12-F12 -> 0
B13: Administración Fiducia | D13: =SUM('budget (8)'!D48:D49) -> 67334346 | E13: =D13/$E$3 -> 1138366 | F13: =SUM('budget (8)'!F48:F49) -> 0 | G13: =SUM('budget (8)'!E48:E49) -> 0 | H13: =SUM('budget (8)'!J48:J49) -> 67334346 | I13: =G13-F13 -> 0
B14: Publicidad | D14: =SUM('budget (8)'!D50:D51) -> 51531388 | E14: =D14/$E$3 -> 871198.44 | F14: =SUM('budget (8)'!F50:F51) -> 390000 | G14: =SUM('budget (8)'!E50:E51) -> 5086501.9 | H14: =SUM('budget (8)'!J50:J51) -> 51531388 | I14: =G14-F14 -> 4696501.9
B15: Post Ventas | D15: =SUM('budget (8)'!D52:D53) -> 19238385 | E15: =D15/$E$3 -> 325247.42 | F15: =SUM('budget (8)'!F52:F53) -> 0 | G15: =SUM('budget (8)'!E52:E53) -> 0 | H15: =SUM('budget (8)'!J52:J53) -> 19238385 | I15: =G15-F15 -> 0
B16: Total Gastos Operativos | D16: =SUM(D11:D15) -> 557226072 | E16: =SUM(E11:E15) -> 9420559.1 | F16: =SUM(F11:F15) -> 390000 | G16: =SUM(G11:G15) -> 1.4250274e+08 | H16: =SUM(H11:H15) -> 557226072 | I16: =G16-F16 -> 1.4211274e+08
B17: Permisos legales y Preliminares | D17: =SUM('budget (8)'!D54:D55) -> 15000000 | E17: =D17/$E$3 -> 253592.56 | F17: =SUM('budget (8)'!F54:F55) -> 0 | G17: =SUM('budget (8)'!E54:E55) -> 3396950.7 | H17: =SUM('budget (8)'!J54:J55) -> 15000000 | I17: =G17-F17 -> 3396950.7
B18: Diseño y Proyecto | D18: =SUM('budget (8)'!D5:D9) -> 20767809 | E18: =D18/$E$3 -> 351104.12 | F18: =SUM('budget (8)'!F5:F9) -> 0 | G18: =SUM('budget (8)'!E5:E9) -> 20727336 | H18: =SUM('budget (8)'!J5:J9) -> 20767809 | I18: =G18-F18 -> 20727336
B19: Gastos Financieros | D19: =SUM('budget (8)'!D58:D59) -> 192383847 | E19: =D19/$E$3 -> 3252474.2 | F19: =SUM('budget (8)'!F58:F59) -> 0 | G19: =SUM('budget (8)'!E58:E59) -> 0 | H19: =SUM('budget (8)'!J58:J59) -> 192383847 | I19: =G19-F19 -> 0
B20: Imprevistos | D20: =SUM('budget (8)'!D56:D57) -> 19238385 | E20: =D20/$E$3 -> 325247.42 | F20: =SUM('budget (8)'!F56:F57) -> 0 | G20: =SUM('budget (8)'!E56:E57) -> 0 | H20: =SUM('budget (8)'!J56:J57) -> 19238385 | I20: =G20-F20 -> 0
B21: Total Otros Gastos | D21: =SUM(D17:D20) -> 2.4739004e+08 | E21: =SUM(E17:E20) -> 4182418.3 | F21: =SUM(F17:F20) -> 0 | G21: =SUM(G17:G20) -> 24124287 | H21: =SUM(H17:H20) -> 2.4739004e+08 | I21: =G21-F21 -> 24124287
B22: Costos Totales de Proyecto | D22: =D5+D10+D16+D21 -> 2.8318398e+09 | E22: =E5+E10+E16+E21 -> 47875566 | F22: =F21+F16+F10+F5 -> 98352415 | G22: =G21+G16+G10+G5 -> 2.7193771e+08 | H22: =H21+H16+H10+H5 -> 2.8318988e+09 | I22: =G22-F22 -> 1.735853e+08
K24: Dato del ADI | L24: 2.8318619e+09
K25: Dato Procore | L25: =D22 -> 2.8318398e+09
K26: Diferencia | L26: =L24-L25 -> 22190.772
B30: ADELANTO AFI | D30: 160000000
B31: Gastado y comprometido | D31: =G22 -> 2.7193771e+08
B32: Disponible | D32: =D30-D31 -> -1.1193771e+08
B34: PARTIDA | D34: MES 1 | E34: MES 2 | F34: MES 3 | G34: MES 4 | H34: MES 5 | I34: MES 6 | J34: MES 7 | K34: MES 8 | L34: MES 9 | M34: Total
B35: gerencias | D35: 1000000 | E35: 1000000 | F35: 1000000 | G35: 1000000 | H35: 1000000 | I35: 1000000 | J35: 1000000 | K35: 1000000 | L35: 1000000 | M35: =SUM(D35:L35) -> 9000000
B36: promocion | D36: 500000 | E36: 500000 | F36: 500000 | G36: 500000 | H36: 500000 | I36: 500000 | J36: 500000 | K36: 500000 | L36: 500000 | M36: =SUM(D36:L36) -> 4500000
B37: atención al cliente | G37: 350000 | H37: 350000 | I37: 350000 | J37: 350000 | K37: 350000 | L37: 350000 | M37: =SUM(D37:L37) -> 2100000
D38: =SUM(D35:D37) -> 1500000 | E38: =SUM(E35:E37) -> 1500000 | F38: =SUM(F35:F37) -> 1500000 | G38: =SUM(G35:G37) -> 1850000 | H38: =SUM(H35:H37) -> 1850000 | I38: =SUM(I35:I37) -> 1850000 | J38: =SUM(J35:J37) -> 1850000 | K38: =SUM(K35:K37) -> 1850000 | L38: =SUM(L35:L37) -> 1850000
B39: Acumulado | E39: =D38+E38 -> 3000000 | F39: =E38+E39 -> 4500000 | G39: =F38+F39 -> 6000000 | H39: =G38+G39 -> 7850000 | I39: =H38+H39 -> 9700000 | J39: =I38+I39 -> 11550000 | K39: =J38+J39 -> 13400000 | L39: =K38+K39 -> 15250000
B41: Disponible | D41: =$D$32-D38 -> -1.1343771e+08 | E41: =$D$32-E39 -> -1.1493771e+08 | F41: =$D$32-F39 -> -1.1643771e+08 | G41: =$D$32-G39 -> -1.1793771e+08 | H41: =$D$32-H39 -> -1.1978771e+08 | I41: =$D$32-I39 -> -1.2163771e+08 | J41: =$D$32-J39 -> -1.2348771e+08 | K41: =$D$32-K39 -> -1.2533771e+08 | L41: =$D$32-L39 -> -1.2718771e+08
K43: =1500000*59 -> 88500000
K44: =K43*3% -> 2655000
D45: 160000000 | K45: 2800000
D46: 119521495 | K46: =SUM(K44:K45) -> 5455000
D47: =D45-D46 -> 40478505
...

Sheet budget (9)
D1: ?
A2: Código de Costo Nivel 1 | B2: Código de Costo Nivel 2 | C2: Código de Costo Nivel 3 | D2: Presupuesto Original | E2: Costos Comprometidos | F2: Costos de Trabajo a la Fecha | G2: Costos Proyectados | H2: Precio unitario del presupuesto | I2: Proyección para terminar | J2: Costo Estimado al Terminar | K2: Proyectado Arriba/Abajo del Presupuesto
A3: 1 - CONSTRUCCION | B3: 1-1 - TERRENO | C3: 1-1-1 - TERRENO ADI | D3: 7172000.3 | E3: 0 | F3: 0 | G3: 0 | H3: 7172000.3 | I3: 7172000.3 | J3: 7172000.3 | K3: 0
A4: 1 - CONSTRUCCION | B4: 1-1 - TERRENO | C4: 1-1-2 - COSTO ASOCIADO TERRENO | D4: 96213169 | E4: 96272169 | F4: 96272169 | G4: 96272169 | H4: 96213169 | I4: 0 | J4: 96272169 | K4: -59000
A5: 1 - CONSTRUCCION | B5: 1-2 - DISEÑO Y PROYECTO | C5: 1-2-1 - DISEÑO Y PROYECTO ADI | D5: 22191.38 | E5: 0 | F5: 0 | G5: 0 | H5: 22191.38 | I5: 22191.38 | J5: 22191.38 | K5: 0
A6: 1 - CONSTRUCCION | B6: 1-2 - DISEÑO Y PROYECTO | C6: 1-2-2 - ESTUDIOS | D6: 0 | E6: 0 | F6: 0 | G6: 0 | I6: 0 | J6: 0 | K6: 0
A7: 1 - CONSTRUCCION | B7: 1-2 - DISEÑO Y PROYECTO | C7: 1-2-2 - ESTUDIOS | D7: 5641221.5 | E7: 5641221.5 | F7: 0 | G7: 5641221.5 | H7: 5641221.5 | I7: 0 | J7: 5641221.5 | K7: 0
A8: 1 - CONSTRUCCION | B8: 1-2 - DISEÑO Y PROYECTO | C8: 1-2-3 - DISEÑO Y ARQUITECTURA | D8: 8804294.6 | E8: 8785614.6 | F8: 0 | G8: 8785614.6 | H8: 8804294.6 | I8: 18680.02 | J8: 8804294.6 | K8: 0
A9: 1 - CONSTRUCCION | B9: 1-2 - DISEÑO Y PROYECTO | C9: 1-2-4 - INGENIERIAS | D9: 5954647.6 | E9: 5932855.3 | F9: 0 | G9: 5932855.3 | H9: 5954647.6 | I9: 21792.24 | J9: 5954647.6 | K9: 0
A10: 1 - CONSTRUCCION | B10: 1-2 - DISEÑO Y PROYECTO | C10: 1-2-5 - COMPUTOS | D10: 367644.95 | E10: 367644.95 | F10: 0 | G10: 367644.95 | H10: 367644.95 | I10: 0 | J10: 367644.95 | K10: 0
A11: 1 - CONSTRUCCION | B11: 1-3 - PRELIMINARES DE OBRA | C11: 1-3-1 - PRELIMINARES DE OBRA ADI | D11: 2608628.3 | E11: 0 | F11: 0 | G11: 0 | H11: 2608628.3 | I11: 2608628.3 | J11: 2608628.3 | K11: 0
A12: 1 - CONSTRUCCION | B12: 1-3 - PRELIMINARES DE OBRA | C12: 1-3-2 - OBRAS PRELIMINARES AREA CAMPAMENTO | D12: 1897166.4 | E12: 1897166.4 | F12: 480315 | G12: 1897166.4 | H12: 1897166.4 | I12: 0 | J12: 1897166.4 | K12: 0
A13: 1 - CONSTRUCCION | B13: 1-3 - PRELIMINARES DE OBRA | C13: 1-3-3 - OBRAS PRELIMINARES AREA SHOWROOM | D13: 7141349 | E13: 7141349 | F13: 2079609.8 | G13: 7141349 | H13: 7141349 | I13: 0 | J13: 7141349 | K13: 0
A14: 1 - CONSTRUCCION | B14: 1-4 - URBANISMO | C14: 1-4-1 - URBANISMO ADI | D14: 11813427 | E14: 0 | F14: 0 | G14: 0 | H14: 11813427 | I14: 11813427 | J14: 11813427 | K14: 0
A15: 1 - CONSTRUCCION | B15: 1-4 - URBANISMO | C15: 1-4-2 - MOVIMIENTO DE TIERRA | D15: 54584720 | E15: 0 | F15: 0 | G15: 0 | H15: 54584720 | I15: 54584720 | J15: 54584720 | K15: 0
A16: 1 - CONSTRUCCION | B16: 1-4 - URBANISMO | C16: 1-4-3 - HIDROSANITARIAS | D16: 56232241 | E16: 0 | F16: 0 | G16: 0 | H16: 56232241 | I16: 56232241 | J16: 56232241 | K16: 0
A17: 1 - CONSTRUCCION | B17: 1-4 - URBANISMO | C17: 1-4-4 - SISTEMAS DE AGUAS | D17: 35679323 | E17: 0 | F17: 0 | G17: 0 | H17: 35679323 | I17: 35679323 | J17: 35679323 | K17: 0
A18: 1 - CONSTRUCCION | B18: 1-4 - URBANISMO | C18: 1-4-6 - INFRAESTRUCTURA ELECTRICA | D18: 1.3513803e+08 | E18: 0 | F18: 0 | G18: 0 | H18: 1.3513803e+08 | I18: 1.3513803e+08 | J18: 1.3513803e+08 | K18: 0
... A27: 1 - CONSTRUCCION | B27: 1-5 - EDIFICACIONES | C27: 1-5-3 - SUPERESTRUCTURA | D27: 2.8304295e+08 | E27: 0 | F27: 0 | G27: 0 | H27: 2.8304295e+08 | I27: 2.8304295e+08 | J27: 2.8304295e+08 | K27: 0
A28: 1 - CONSTRUCCION | B28: 1-5 - EDIFICACIONES | C28: 1-5-4 - INSTALACIONES ELECTRICAS | D28: 0 | E28: 0 | F28: 0 | G28: 0 | I28: 0 | J28: 0 | K28: 0
A29: 1 - CONSTRUCCION | B29: 1-5 - EDIFICACIONES | C29: 1-5-4 - INSTALACIONES ELECTRICAS | D29: 60439200 | E29: 0 | F29: 0 | G29: 0 | H29: 60439200 | I29: 60439200 | J29: 60439200 | K29: 0
A30: 1 - CONSTRUCCION | B30: 1-5 - EDIFICACIONES | C30: 1-5-5 - TELECOMUNICACIONES | D30: 8446912.3 | E30: 0 | F30: 0 | G30: 0 | H30: 8446912.3 | I30: 8446912.3 | J30: 8446912.3 | K30: 0
A31: 1 - CONSTRUCCION | B31: 1-5 - EDIFICACIONES | C31: 1-5-6 - INSTALACIONES SANITARIAS | D31: 1.0100749e+08 | E31: 0 | F31: 0 | G31: 0 | H31: 1.0100749e+08 | I31: 1.0100749e+08 | J31: 1.0100749e+08 | K31: 0
A32: 1 - CONSTRUCCION | B32: 1-5 - EDIFICACIONES | C32: 1-5-7 - INSTALACIONES MECANICAS | D32: 455797.65 | E32: 0 | F32: 0 | G32: 0 | H32: 455797.65 | I32: 455797.65 | J32: 455797.65 | K32: 0
A33: 1 - CONSTRUCCION | B33: 1-5 - EDIFICACIONES | C33: 1-5-8 - ALBANILERIA | D33: 79619986 | E33: 0 | F33: 0 | G33: 0 | H33: 79619986 | I33: 79619986 | J33: 79619986 | K33: 0
A34: 1 - CONSTRUCCION | B34: 1-5 - EDIFICACIONES | C34: 1-5-9 - HERRERIA | D34: 55148949 | E34: 0 | F34: 0 | G34: 0 | H34: 55148949 | I34: 55148949 | J34: 55148949 | K34: 0
A35: 1 - CONSTRUCCION | B35: 1-5 - EDIFICACIONES | C35: 1-5-10 - REVESTIMIENTO | D35: 1.7979257e+08 | E35: 0 | F35: 0 | G35: 0 | H35: 1.7979257e+08 | I35: 1.7979257e+08 | J35: 1.7979257e+08 | K35: 0
A36: 1 - CONSTRUCCION | B36: 1-5 - EDIFICACIONES | C36: 1-5-11 - CARPINTERIA | D36: 1.1340591e+08 | E36: 0 | F36: 0 | G36: 0 | H36: 1.1340591e+08 | I36: 1.1340591e+08 | J36: 1.1340591e+08 | K36: 0
A37: 1 - CONSTRUCCION | B37: 1-5 - EDIFICACIONES | C37: 1-5-12 - VENTANERIA | D37: 95070320 | E37: 0 | F37: 0 | G37: 0 | H37: 95070320 | I37: 95070320 | J37: 95070320 | K37: 0
A38: 1 - CONSTRUCCION | B38: 1-5 - EDIFICACIONES | C38: 1-5-13 - PINTURA | D38: 1.2190433e+08 | E38: 0 | F38: 0 | G38: 0 | H38: 1.2190433e+08 | I38: 1.2190433e+08 | J38: 1.2190433e+08 | K38: 0
A39: 1 - CONSTRUCCION | B39: 1-5 - EDIFICACIONES | C39: 1-5-14 - MISCELANEOS | D39: 74569125 | E39: 0 | F39: 0 | G39: 0 | H39: 74569125 | I39: 74569125 | J39: 74569125 | K39: 0
A40: 1 - CONSTRUCCION | B40: 1-6 - GERENCIA DE CONSTRUCCION | C40: 1-6-1 - GERENCIA DE CONSTRUCCION ADI | D40: 0 | E40: 0 | F40: 0 | G40: 0 | I40: 0 | J40: 0 | K40: 0
A41: 1 - CONSTRUCCION | B41: 1-6 - GERENCIA DE CONSTRUCCION | C41: 1-6-1 - GERENCIA DE CONSTRUCCION ADI | D41: 171771292 | E41: 0 | F41: 0 | G41: 0 | H41: 171771292 | I41: 171771292 | J41: 171771292 | K41: 0
A42: 1 - CONSTRUCCION | B42: 1-6 - GERENCIA DE CONSTRUCCION | C42: 1-6-2 - COSTO GERENCIA DE CONSTRUCCION | D42: 0 | E42: 0 | F42: 0 | G42: 0 | H42: 0 | I42: 0 | J42: 0 | K42: 0
A43: 1 - CONSTRUCCION | B43: 1-7 - INDIRECTOS DE OBRA | C43: 1-7-1 - INDIRECTOS DE OBRA ADI | D43: 34354258 | E43: 0 | F43: 0 | G43: 0 | H43: 34354258 | I43: 34354258 | J43: 34354258 | K43: 0
A44: 1 - CONSTRUCCION | B44: 1-7 - INDIRECTOS DE OBRA | C44: 1-7-2 - COSTOS INDIRECTOS DE OBRA | D44: 0 | E44: 0 | F44: 0 | G44: 0 | H44: 0 | I44: 0 | J44: 0 | K44: 0
A45: 2 - OPERATIVO | B45: 2-1 - GERENCIA DE LA PROMOTORA | C45: 2-1-1 - GERENCIA DE LA PROMOTORA ADI | D45: 137417034 | E45: 137416238 | F45: 0 | G45: 137416238 | H45: 137417034 | I45: 796 | J45: 137417034 | K45: 0
A46: 2 - OPERATIVO | B46: 2-1 - GERENCIA DE LA PROMOTORA | C46: 2-1-2 - COSTO GERENCIA DE LA PROMOTORA ADI | D46: 0 | E46: 0 | F46: 0 | G46: 0 | H46: 0 | I46: 0 | J46: 0 | K46: 0
A47: 2 - OPERATIVO | B47: 2-2 - GERENCIA DE VENTAS | C47: 2-2-1 - COSTO GERENCIA DE VENTAS | D47: 0 | E47: 0 | F47: 0 | G47: 0 | H47: 0 | I47: 0 | J47: 0 | K47: 0
A48: 2 - OPERATIVO | B48: 2-2 - GERENCIA DE VENTAS | C48: 2-2-2 - ADMINISTRACION DE VENTAS | D48: 35151584 | E48: 0 | F48: 0 | G48: 0 | H48: 35151584 | I48: 35151584 | J48: 35151584 | K48: 0
...

Sheet PRESENTACIÓN ABRIL 24 v1
E1: cambiar a la fecha del adi marzo 2024 | K1: IMAGEN DEL ADI archivo : Flujo_de_caja_PUNTA_CANA_462_MAR2024_V.0.XLSX al 02/05/24
E2: TC al 7 de mayo | F2: a | G2: b | H2: d | I2: c
B3: PRESUPUESTO ABRIL 2024 | E3: 59.15 | F3: TOTAL EJECUTADO | G3: COMPROMETIDO | H3: POR EJECUTAR | I3: PROYECTADO PARA TERMINAR
B4: PARTIDA | D4: DOP | E4: US $
B5: Terreno | D5: =SUM('budget (9)'!D3:D4) -> 103385169 | E5: =D5/E3 -> 1747847.3 | F5: =SUM('budget (9)'!F3:F4) -> 96272169 | G5: =SUM('budget (9)'!E3:E4) -> 96272169 | H5: =G5-F5 -> 0 | I5: =SUM('budget (9)'!I3:I4) -> 7172000.3 | J5: =D5-(G5+I5) -> -59000
B6: Costo Urbanismo | D6: =SUM('budget (9)'!D11:D24) -> 4.51759e+08 | E6: =D6/$E$3 -> 7637514.8 | F6: =SUM('budget (9)'!F11:F24) -> 2559924.8 | G6: =SUM('budget (9)'!E11:E24) -> 9038515.4 | H6: =G6-F6 -> 6478590.6 | I6: =SUM('budget (9)'!I11:I24) -> 4.4272048e+08 | J6: =D6-(G6+I6) -> 0
B7: Costo Vivienda | D7: =SUM('budget (9)'!D25:D39) -> 1265953920 | E7: =D7/$E$3 -> 21402433 | F7: =SUM('budget (9)'!F25:F39) -> 0 | G7: =SUM('budget (9)'!E25:E39) -> 0 | H7: =G7-F7 -> 0 | I7: =SUM('budget (9)'!I25:I39) -> 1265953920 | J7: =D7-(G7+I7) -> 0
B8: Gerencia Construcción: | D8: =SUM('budget (9)'!D40:D41) -> 171771292 | E8: =D8/$E$3 -> 2903994.8 | F8: =SUM('budget (9)'!F40:F41) -> 0 | G8: =SUM('budget (9)'!E40:E41) -> 0 | H8: =G8-F8 -> 0 | I8: =SUM('budget (9)'!I40:I41) -> 171771292 | J8: =D8-(G8+I8) -> 0
B9: Indirectos de Obra | D9: =SUM('budget (9)'!D42:D43) -> 34354258 | E9: =D9/$E$3 -> 580798.95 | F9: =SUM('budget (9)'!F42:F43) -> 0 | G9: =SUM('budget (9)'!E42:E43) -> 0 | H9: =G9-F9 -> 0 | I9: =SUM('budget (9)'!I42:I43) -> 34354258 | J9: =D9-(G9+I9) -> 0
B10: Total Costos Construcción | D10: =SUM(D6:D9) -> 1923838470 | E10: =SUM(E6:E9) -> 32524742 | F10: =SUM(F6:F9) -> 2559924.8 | G10: =SUM(G6:G9) -> 9038515.4 | H10: =G10-F10 -> 6478590.6 | I10: =SUM(I6:I9) -> 1.9148e+09 | J10: =D10-(G10+I10) -> 0
B11: Gerencia de la Promotora | D11: =SUM('budget (9)'!D44:D45) -> 137417034 | E11: =D11/$E$3 -> 2323195.8 | F11: =SUM('budget (9)'!F44:F45) -> 0 | G11: =SUM('budget (9)'!E44:E45) -> 137416238 | H11: =G11-F11 -> 137416238 | I11: =SUM('budget (9)'!I44:I45) -> 796 | J11: =D11-(G11+I11) -> 0
B12: Gerencia de Ventas | D12: =SUM('budget (9)'!D46:D48) -> 35151584 | E12: =D12/$E$3 -> 594278.68 | F12: =SUM('budget (9)'!F46:F48) -> 0 | G12: =SUM('budget (9)'!E46:E48) -> 0 | H12: =G12-F12 -> 0 | I12: =SUM('budget (9)'!I46:I48) -> 35151584 | J12: =D12-(G12+I12) -> 0
B13: Administración Fiducia | D13: =SUM('budget (9)'!D49:D50) -> 313887681 | E13: =D13/$E$3 -> 5306638.7 | F13: =SUM('budget (9)'!F49:F50) -> 0 | G13: =SUM('budget (9)'!E49:E50) -> 0 | H13: =G13-F13 -> 0 | I13: =SUM('budget (9)'!I49:I50) -> 313887681 | J13: =D13-(G13+I13) -> 0
B14: Publicidad | D14: =SUM('budget (9)'!D51:D52) -> 50231388 | E14: =D14/$E$3 -> 849220.42 | F14: =SUM('budget (9)'!F51:F52) -> 0 | G14: =SUM('budget (9)'!E51:E52) -> 3786501.9 | H14: =G14-F14 -> 3786501.9 | I14: =SUM('budget (9)'!I51:I52) -> 46444886 | J14: =D14-(G14+I14) -> 0
B15: Post Ventas | D15: =SUM('budget (9)'!D53:D54) -> 20538385 | E15: =D15/$E$3 -> 347225.44 | F15: =SUM('budget (9)'!F53:F54) -> 0 | G15: =SUM('budget (9)'!E53:E54) -> 0 | H15: =G15-F15 -> 0 | I15: =SUM('budget (9)'!I53:I54) -> 20538385 | J15: =D15-(G15+I15) -> 0
B16: Total Gastos Operativos | D16: =SUM(D11:D15) -> 557226072 | E16: =SUM(E11:E15) -> 9420559.1 | F16: =SUM(F11:F15) -> 0 | G16: =SUM(G11:G15) -> 1.4120274e+08 | H16: =G16-F16 -> 1.4120274e+08 | I16: =SUM(I11:I15) -> 4.1602333e+08 | J16: =D16-(G16+I16) -> 0
B17: Permisos legales y Preliminares | D17: =SUM('budget (9)'!D55:D56) -> 11603049 | E17: =D17/$E$3 -> 196163.13 | F17: =SUM('budget (9)'!F55:F56) -> 3634527.5 | G17: =SUM('budget (9)'!E55:E56) -> 3634527.5 | H17: =G17-F17 -> 0 | I17: =SUM('budget (9)'!I55:I56) -> 7968521.8 | J17: =D17-(G17+I17) -> 0
B18: Diseño y Proyecto | D18: =SUM('budget (9)'!D5:D10) -> 20790000 | E18: =D18/$E$3 -> 351479.29 | F18: =SUM('budget (9)'!F5:F10) -> 0 | G18: =SUM('budget (9)'!E5:E10) -> 20727336 | H18: =G18-F18 -> 20727336 | I18: =SUM('budget (9)'!I5:I10) -> 62663.64 | J18: =D18-(G18+I18) -> 0
B19: Gastos Financieros | D19: =SUM('budget (9)'!D59:D60) -> 192383847 | E19: =D19/$E$3 -> 3252474.2 | F19: =SUM('budget (9)'!F59:F60) -> 0 | G19: =SUM('budget (9)'!E59:E60) -> 0 | H19: =G19-F19 -> 0 | I19: =SUM('budget (9)'!I59:I60) -> 192383847 | J19: =D19-(G19+I19) -> 0
B20: Imprevistos | D20: =SUM('budget (9)'!D57:D58) -> 22635336 | E20: =D20/$E$3 -> 382676.85 | F20: =SUM('budget (9)'!F57:F58) -> 1009477.9 | G20: =SUM('budget (9)'!E57:E58) -> 3396950.7 | H20: =G20-F20 -> 2387472.8 | I20: =SUM('budget (9)'!I57:I58) -> 19238385 | J20: =D20-(G20+I20) -> 0
B21: Total Otros Gastos | D21: =SUM(D17:D20) -> 247412232 | E21: =SUM(E17:E20) -> 4182793.4 | F21: =SUM(F17:F20) -> 4644005.4 | G21: =SUM(G17:G20) -> 27758815 | H21: =G21-F21 -> 23114809 | I21: =SUM(I17:I20) -> 2.1965342e+08 | J21: =D21-(G21+I21) -> 0
B22: Costos Totales de Proyecto | D22: =D5+D10+D16+D21 -> 2831861943 | E22: =E5+E10+E16+E21 -> 47875942 | F22: =F21+F16+F10+F5 -> 103476099 | G22: =G21+G16+G10+G5 -> 2.7427224e+08 | H22: =G22-F22 -> 1.7079614e+08 | I22: =I21+I16+I10+I5 -> 2.5576487e+09 | J22: =J21+J16+J10+J5 -> -59000
L24: Dato del ADI | M24: 2.8318619e+09
L25: Dato Procore | M25: =D22 -> 2831861943
L26: Diferencia | M26: =M24-M25 -> -0.6079998
B30: ADELANTO AFI | D30: 160000000
B31: Gastado y comprometido
B32: Disponible | D32: =D30-D31 -> 160000000
B34: PARTIDA | D34: MES 1 | E34: MES 2 | F34: MES 3 | G34: MES 4 | H34: MES 5 | I34: MES 6 | K34: MES 7 | L34: MES 8 | M34: MES 9 | N34: Total
B35: gerencias | D35: 1000000 | E35: 1000000 | F35: 1000000 | G35: 1000000 | H35: 1000000 | I35: 1000000 | K35: 1000000 | L35: 1000000 | M35: 1000000 | N35: =SUM(D35:M35) -> 9000000
B36: promocion | D36: 500000 | E36: 500000 | F36: 500000 | G36: 500000 | H36: 500000 | I36: 500000 | K36: 500000 | L36: 500000 | M36: 500000 | N36: =SUM(D36:M36) -> 4500000
A37: meter gastos operativos | B37: atención al cliente | G37: 350000 | H37: 350000 | I37: 350000 | K37: 350000 | L37: 350000 | M37: 350000 | N37: =SUM(D37:M37) -> 2100000
D38: =SUM(D35:D37) -> 1500000 | E38: =SUM(E35:E37) -> 1500000 | F38: =SUM(F35:F37) -> 1500000 | G38: =SUM(G35:G37) -> 1850000 | H38: =SUM(H35:H37) -> 1850000 | I38: =SUM(I35:I37) -> 1850000 | K38: =SUM(K35:K37) -> 1850000 | L38: =SUM(L35:L37) -> 1850000 | M38: =SUM(M35:M37) -> 1850000
B39: Acumulado | E39: =D38+E38 -> 3000000 | F39: =E38+E39 -> 4500000 | G39: =F38+F39 -> 6000000 | H39: =G38+G39 -> 7850000 | I39: =H38+H39 -> 9700000 | K39: =I38+I39 -> 11550000 | L39: =K38+K39 -> 13400000 | M39: =L38+L39 -> 15250000
B41: Disponible | D41: =$D$32-D38 -> 158500000 | E41: =$D$32-E39 -> 157000000 | F41: =$D$32-F39 -> 155500000 | G41: =$D$32-G39 -> 154000000 | H41: =$D$32-H39 -> 152150000 | I41: =$D$32-I39 -> 150300000 | K41: =$D$32-K39 -> 148450000 | L41: =$D$32-L39 -> 146600000 | M41: =$D$32-M39 -> 144750000
L43: =1500000*59 -> 88500000
L44: =L43*3% -> 2655000
D45: 160000000 | L45: 2800000
D46: 119521495 | L46: =SUM(L44:L45) -> 5455000
D47: =D45-D46 -> 40478505
...

Sheet BITACORA Y AJUSTES AL ARCHIVO
B2: FECHA | C2: EXPLICACIÓN | D2: ACCIÓN REQUERIDA | E2: RESPONSABLE | F2: FECHA | G2: SEGUIMIENTO
B3: 45414 | C3: Falta permiso de agua | D3: Actualizar el monto en el ADI | E3: PLA / RQ | F3: 45415
B4: 45414 | C4: Impuesto de transferencia del activo | D4: Actualizar el monto en el ADI | E4: PLA / RQ

Sheet PRESENTACIÓN 2 meses
D1: TOTAL EJECUTADO | H1: COMPROMETIDO | L1: POR EJECUTAR
D3: 45352 | E3: 45383 | F3: 45413 | G3: var% | H3: 45352 | I3: 45383 | J3: 45413 | K3: var% | L3: 45352 | M3: 45383 | N3: 45413 | O3: var%
B4: Terreno | D4: ='PRESENTACIÓN MARZO 24'!I5 -> 96213169 | E4: ='PRESENTACIÓN ABRIL 24 v1'!F5 -> 96272169 | F4: ='PRESENTACIÓN Al 29 de mayo'!#REF! -> #REF! | G4: =(F4/E4)-1 -> #REF! | H4: ='PRESENTACIÓN MARZO 24'!J5 -> 96213169 | I4: ='PRESENTACIÓN ABRIL 24 v1'!G5 -> 96272169 | J4: ='PRESENTACIÓN Al 29 de mayo'!E5 -> 94032040 | L4: ='PRESENTACIÓN MARZO 24'!L5 -> 0 | M4: ='PRESENTACIÓN ABRIL 24 v1'!H5 -> 0 | N4: ='PRESENTACIÓN Al 29 de mayo'!G5 -> 59000
B5: Costo Urbanismo | D5: ='PRESENTACIÓN MARZO 24'!I6 -> 9038515 | E5: ='PRESENTACIÓN ABRIL 24 v1'!F6 -> 2559924.8 | F5: ='PRESENTACIÓN Al 29 de mayo'!#REF! -> #REF! | G5: =(F5-E5) -> #REF! | H5: ='PRESENTACIÓN MARZO 24'!J6 -> 9038515 | I5: ='PRESENTACIÓN ABRIL 24 v1'!G6 -> 9038515.4 | J5: ='PRESENTACIÓN Al 29 de mayo'!E6 -> 9038515.4 | L5: ='PRESENTACIÓN MARZO 24'!L6 -> 0 | M5: ='PRESENTACIÓN ABRIL 24 v1'!H6 -> 6478590.6 | N5: ='PRESENTACIÓN Al 29 de mayo'!G6 -> 0
B6: Costo Vivienda | D6: ='PRESENTACIÓN MARZO 24'!I7 -> 0 | E6: ='PRESENTACIÓN ABRIL 24 v1'!F7 -> 0 | F6: ='PRESENTACIÓN Al 29 de mayo'!#REF! -> #REF! | H6: ='PRESENTACIÓN MARZO 24'!J7 -> 0 | I6: ='PRESENTACIÓN ABRIL 24 v1'!G7 -> 0 | J6: ='PRESENTACIÓN Al 29 de mayo'!E7 -> 0 | L6: ='PRESENTACIÓN MARZO 24'!L7 -> 0 | M6: ='PRESENTACIÓN ABRIL 24 v1'!H7 -> 0 | N6: ='PRESENTACIÓN Al 29 de mayo'!G7 -> 0
B7: Gerencia Construcción: | D7: ='PRESENTACIÓN MARZO 24'!I8 -> 0 | E7: ='PRESENTACIÓN ABRIL 24 v1'!F8 -> 0 | F7: ='PRESENTACIÓN Al 29 de mayo'!#REF! -> #REF! | H7: ='PRESENTACIÓN MARZO 24'!J8 -> 0 | I7: ='PRESENTACIÓN ABRIL 24 v1'!G8 -> 0 | J7: ='PRESENTACIÓN Al 29 de mayo'!E8 -> 171771292 | L7: ='PRESENTACIÓN MARZO 24'!L8 -> 0 | M7: ='PRESENTACIÓN ABRIL 24 v1'!H8 -> 0 | N7: ='PRESENTACIÓN Al 29 de mayo'!G8 -> 171771292
B8: Indirectos de Obra | D8: ='PRESENTACIÓN MARZO 24'!I9 -> 0 | E8: ='PRESENTACIÓN ABRIL 24 v1'!F9 -> 0 | F8: ='PRESENTACIÓN Al 29 de mayo'!#REF! -> #REF! | H8: ='PRESENTACIÓN MARZO 24'!J9 -> 0 | I8: ='PRESENTACIÓN ABRIL 24 v1'!G9 -> 0 | J8: ='PRESENTACIÓN Al 29 de mayo'!E9 -> 0 | L8: ='PRESENTACIÓN MARZO 24'!L9 -> 0 | M8: ='PRESENTACIÓN ABRIL 24 v1'!H9 -> 0 | N8: ='PRESENTACIÓN Al 29 de mayo'!G9 -> 0
B9: Total Costos Construcción | D9: ='PRESENTACIÓN MARZO 24'!I10 -> 9038515 | E9: ='PRESENTACIÓN ABRIL 24 v1'!F10 -> 2559924.8 | F9: ='PRESENTACIÓN Al 29 de mayo'!#REF! -> #REF! | H9: ='PRESENTACIÓN MARZO 24'!J10 -> 9038515 | I9: ='PRESENTACIÓN ABRIL 24 v1'!G10 -> 9038515.4 | J9: ='PRESENTACIÓN Al 29 de mayo'!E10 -> 1.8080981e+08 | L9: ='PRESENTACIÓN MARZO 24'!L10 -> 0 | M9: ='PRESENTACIÓN ABRIL 24 v1'!H10 -> 6478590.6 | N9: ='PRESENTACIÓN Al 29 de mayo'!G10 -> 171771292
B10: Gerencia de la Promotora | D10: ='PRESENTACIÓN MARZO 24'!I11 -> 0 | E10: ='PRESENTACIÓN ABRIL 24 v1'!F11 -> 0 | F10: ='PRESENTACIÓN Al 29 de mayo'!#REF! -> #REF! | H10: ='PRESENTACIÓN MARZO 24'!J11 -> 0 | I10: ='PRESENTACIÓN ABRIL 24 v1'!G11 -> 137416238 | J10: ='PRESENTACIÓN Al 29 de mayo'!E11 -> 137416238 | L10: ='PRESENTACIÓN MARZO 24'!L11 -> 0 | M10: ='PRESENTACIÓN ABRIL 24 v1'!H11 -> 137416238 | N10: ='PRESENTACIÓN Al 29 de mayo'!G11 -> 137416238
B11: Gerencia de Ventas | D11: ='PRESENTACIÓN MARZO 24'!I12 -> 0 | E11: ='PRESENTACIÓN ABRIL 24 v1'!F12 -> 0 | F11: ='PRESENTACIÓN Al 29 de mayo'!#REF! -> #REF! | H11: ='PRESENTACIÓN MARZO 24'!J12 -> 0 | I11: ='PRESENTACIÓN ABRIL 24 v1'!G12 -> 0 | J11: ='PRESENTACIÓN Al 29 de mayo'!E12 -> 35151584 | L11: ='PRESENTACIÓN MARZO 24'!L12 -> 0 | M11: ='PRESENTACIÓN ABRIL 24 v1'!H12 -> 0 | N11: ='PRESENTACIÓN Al 29 de mayo'!G12 -> 35151584
B12: Administración Fiducia | D12: ='PRESENTACIÓN MARZO 24'!I13 -> 0 | E12: ='PRESENTACIÓN ABRIL 24 v1'!F13 -> 0 | F12: ='PRESENTACIÓN Al 29 de mayo'!#REF! -> #REF! | H12: ='PRESENTACIÓN MARZO 24'!J13 -> 0 | I12: ='PRESENTACIÓN ABRIL 24 v1'!G13 -> 0 | J12: ='PRESENTACIÓN Al 29 de mayo'!E13 -> 0 | L12: ='PRESENTACIÓN MARZO 24'!L13 -> 0 | M12: ='PRESENTACIÓN ABRIL 24 v1'!H13 -> 0 | N12: ='PRESENTACIÓN Al 29 de mayo'!G13 -> 0
B13: Publicidad | D13: ='PRESENTACIÓN MARZO 24'!I14 -> 446334.38 | E13: ='PRESENTACIÓN ABRIL 24 v1'!F14 -> 0 | F13: ='PRESENTACIÓN Al 29 de mayo'!#REF! -> #REF! | H13: ='PRESENTACIÓN MARZO 24'!J14 -> 3786501.9 | I13: ='PRESENTACIÓN ABRIL 24 v1'!G14 -> 3786501.9 | J13: ='PRESENTACIÓN Al 29 de mayo'!E14 -> 3839208.5 | L13: ='PRESENTACIÓN MARZO 24'!L14 -> 3340167.5 | M13: ='PRESENTACIÓN ABRIL 24 v1'!H14 -> 3786501.9 | N13: ='PRESENTACIÓN Al 29 de mayo'!G14 -> 2390947.5
B14: Post Ventas | D14: ='PRESENTACIÓN MARZO 24'!I15 -> 0 | E14: ='PRESENTACIÓN ABRIL 24 v1'!F15 -> 0 | F14: ='PRESENTACIÓN Al 29 de mayo'!#REF! -> #REF! | H14: ='PRESENTACIÓN MARZO 24'!J15 -> 0 | I14: ='PRESENTACIÓN ABRIL 24 v1'!G15 -> 0 | J14: ='PRESENTACIÓN Al 29 de mayo'!E15 -> 0 | L14: ='PRESENTACIÓN MARZO 24'!L15 -> 0 | M14: ='PRESENTACIÓN ABRIL 24 v1'!H15 -> 0 | N14: ='PRESENTACIÓN Al 29 de mayo'!G15 -> 0
B15: Total Gastos Operativos | D15: ='PRESENTACIÓN MARZO 24'!I16 -> 446334.38 | E15: ='PRESENTACIÓN ABRIL 24 v1'!F16 -> 0 | F15: ='PRESENTACIÓN Al 29 de mayo'!#REF! -> #REF! | H15: ='PRESENTACIÓN MARZO 24'!J16 -> 3786501.9 | I15: ='PRESENTACIÓN ABRIL 24 v1'!G16 -> 1.4120274e+08 | J15: ='PRESENTACIÓN Al 29 de mayo'!E16 -> 1.7640703e+08 | L15: ='PRESENTACIÓN MARZO 24'!L16 -> 3340167.5 | M15: ='PRESENTACIÓN ABRIL 24 v1'!H16 -> 1.4120274e+08 | N15: ='PRESENTACIÓN Al 29 de mayo'!G16 -> 1.7495877e+08
B16: Permisos legales y Preliminares | D16: ='PRESENTACIÓN MARZO 24'!I17 -> 1576990 | E16: ='PRESENTACIÓN ABRIL 24 v1'!F17 -> 3634527.5 | F16: ='PRESENTACIÓN Al 29 de mayo'!#REF! -> #REF! | H16: ='PRESENTACIÓN MARZO 24'!J17 -> 13841815 | I16: ='PRESENTACIÓN ABRIL 24 v1'!G17 -> 3634527.5 | J16: ='PRESENTACIÓN Al 29 de mayo'!E17 -> 18740000 | L16: ='PRESENTACIÓN MARZO 24'!L17 -> 12264825 | M16: ='PRESENTACIÓN ABRIL 24 v1'!H17 -> 0 | N16: ='PRESENTACIÓN Al 29 de mayo'!G17 -> 13528482
B17: Diseño y Proyecto | D17: ='PRESENTACIÓN MARZO 24'!I18 -> 12246487 | E17: ='PRESENTACIÓN ABRIL 24 v1'!F18 -> 0 | F17: ='PRESENTACIÓN Al 29 de mayo'!#REF! -> #REF! | H17: ='PRESENTACIÓN MARZO 24'!J18 -> 20546016 | I17: ='PRESENTACIÓN ABRIL 24 v1'!G18 -> 20727336 | J17: ='PRESENTACIÓN Al 29 de mayo'!E18 -> 20727336 | L17: ='PRESENTACIÓN MARZO 24'!L18 -> 8299529.8 | M17: ='PRESENTACIÓN ABRIL 24 v1'!H18 -> 20727336 | N17: ='PRESENTACIÓN Al 29 de mayo'!G18 -> 8480849.8
... B20: Total Otros Gastos | D20: ='PRESENTACIÓN MARZO 24'!I21 -> 13823477 | E20: ='PRESENTACIÓN ABRIL 24 v1'!F21 -> 4644005.4 | F20: ='PRESENTACIÓN Al 29 de mayo'!#REF! -> #REF! | H20: ='PRESENTACIÓN MARZO 24'!J21 -> 34387831 | I20: ='PRESENTACIÓN ABRIL 24 v1'!G21 -> 27758815 | J20: ='PRESENTACIÓN Al 29 de mayo'!E21 -> 39467336 | L20: ='PRESENTACIÓN MARZO 24'!L21 -> 20564355 | M20: ='PRESENTACIÓN ABRIL 24 v1'!H21 -> 23114809 | N20: ='PRESENTACIÓN Al 29 de mayo'!G21 -> 22009332
B21: Costos Totales de Proyecto | D21: =D20+D15+D9+D4 -> 1.1952149e+08 | E21: ='PRESENTACIÓN ABRIL 24 v1'!F22 -> 103476099 | F21: ='PRESENTACIÓN Al 29 de mayo'!#REF! -> #REF! | H21: =H20+H15+H9+H4 -> 1.4342602e+08 | I21: ='PRESENTACIÓN ABRIL 24 v1'!G22 -> 2.7427224e+08 | J21: ='PRESENTACIÓN Al 29 de mayo'!E22 -> 4.9071621e+08 | L21: =H21-D21 -> 23904522 | M21: 23114809 | N21: ='PRESENTACIÓN Al 29 de mayo'!G22 -> 3.6879839e+08

Sheet budget (11)
A1: Código de Costo Nivel 1 | B1: Código de Costo Nivel 2 | C1: Código de Costo Nivel 3 | D1: Presupuesto Original | E1: Costos Comprometidos | F1: Costos de Trabajo a la Fecha | G1: Costos Proyectados | H1: Precio unitario del presupuesto | I1: Proyección para terminar | J1: Costo Estimado al Terminar | K1: Proyectado Arriba/Abajo del Presupuesto
A2: 1 - CONSTRUCCION | B2: 1-1 - TERRENO | C2: 1-1-1 - TERRENO ADI | D2: 7113000.3 | E2: 0 | F2: 0 | G2: 0 | H2: 7113000.3 | I2: 7113000.3 | J2: 7113000.3 | K2: 0
A3: 1 - CONSTRUCCION | B3: 1-1 - TERRENO | C3: 1-1-2 - COSTO ASOCIADO TERRENO | D3: 96272169 | E3: 94032040 | F3: 94032040 | G3: 94032040 | H3: 96272169 | I3: 2240128.9 | J3: 96272169 | K3: 0
A4: 1 - CONSTRUCCION | B4: 1-2 - DISEÑO Y PROYECTO | C4: 1-2-1 - DISEÑO Y PROYECTO ADI | D4: 62663.64 | E4: 0 | F4: 0 | G4: 0 | H4: 62663.64 | I4: 62663.64 | J4: 62663.64
A5: 1 - CONSTRUCCION | B5: 1-2 - DISEÑO Y PROYECTO | C5: 1-2-2 - ESTUDIOS | D5: 0 | E5: 0 | F5: 0 | G5: 0 | I5: 0 | J5: 0 | K5: 0
A6: 1 - CONSTRUCCION | B6: 1-2 - DISEÑO Y PROYECTO | C6: 1-2-2 - ESTUDIOS | D6: 5641221.5 | E6: 5641221.5 | F6: 0 | G6: 5641221.5 | H6: 5641221.5 | I6: 0 | J6: 5641221.5 | K6: 0
A7: 1 - CONSTRUCCION | B7: 1-2 - DISEÑO Y PROYECTO | C7: 1-2-3 - DISEÑO Y ARQUITECTURA | D7: 8785614.6 | E7: 8785614.6 | F7: 0 | G7: 8785614.6 | H7: 8785614.6 | I7: 0 | J7: 8785614.6 | K7: 0
A8: 1 - CONSTRUCCION | B8: 1-2 - DISEÑO Y PROYECTO | C8: 1-2-4 - INGENIERIAS | D8: 5932855.3 | E8: 5932855.3 | F8: 0 | G8: 5932855.3 | H8: 5932855.3 | I8: 0 | J8: 5932855.3 | K8: 0
A9: 1 - CONSTRUCCION | B9: 1-2 - DISEÑO Y PROYECTO | C9: 1-2-5 - COMPUTOS | D9: 367644.95 | E9: 367644.95 | F9: 0 | G9: 367644.95 | H9: 367644.95 | I9: 0 | J9: 367644.95 | K9: 0
A10: 1 - CONSTRUCCION | B10: 1-3 - PRELIMINARES DE OBRA. | C10: 1-3-2 - OBRAS PRELIMINARES AREA CAMPAMENTO | D10: 0 | E10: 0 | F10: 0 | G10: 0 | I10: 0 | J10: 0 | K10: 0
A11: 1 - CONSTRUCCION | B11: 1-4 - URBANISMO | C11: 1-4-1 - URBANISMO ADI | D11: 11813427 | E11: 0 | F11: 0 | G11: 0 | H11: 11813427 | I11: 11813427 | J11: 11813427 | K11: 0
A12: 1 - CONSTRUCCION | B12: 1-4 - URBANISMO | C12: 1-4-2 - PRELIMINARES ADI | D12: 2608627.8 | E12: 0 | F12: 0 | G12: 0 | H12: 2608627.8 | I12: 2608627.8 | J12: 2608627.8 | K12: 0
